[2022-12-06 08:17:42,690] {taskinstance.py:896} INFO - Dependencies all met for <TaskInstance: my_elastic_search_dag.CheckElasticSearchConnexion 2022-12-05T00:00:00+00:00 [queued]>
[2022-12-06 08:17:42,703] {taskinstance.py:896} INFO - Dependencies all met for <TaskInstance: my_elastic_search_dag.CheckElasticSearchConnexion 2022-12-05T00:00:00+00:00 [queued]>
[2022-12-06 08:17:42,703] {taskinstance.py:1087} INFO - 
--------------------------------------------------------------------------------
[2022-12-06 08:17:42,704] {taskinstance.py:1088} INFO - Starting attempt 2 of 51
[2022-12-06 08:17:42,704] {taskinstance.py:1089} INFO - 
--------------------------------------------------------------------------------
[2022-12-06 08:17:42,710] {taskinstance.py:1107} INFO - Executing <Task(PythonOperator): CheckElasticSearchConnexion> on 2022-12-05T00:00:00+00:00
[2022-12-06 08:17:42,713] {standard_task_runner.py:52} INFO - Started process 305 to run task
[2022-12-06 08:17:42,716] {standard_task_runner.py:76} INFO - Running: ['***', 'tasks', 'run', 'my_elastic_search_dag', 'CheckElasticSearchConnexion', '2022-12-05T00:00:00+00:00', '--job-id', '4', '--pool', 'default_pool', '--raw', '--subdir', 'DAGS_FOLDER/my_elastic_search_dag.py', '--cfg-path', '/tmp/tmpqtyumohz', '--error-file', '/tmp/tmpch57bglu']
[2022-12-06 08:17:42,717] {standard_task_runner.py:77} INFO - Job 4: Subtask CheckElasticSearchConnexion
[2022-12-06 08:17:42,753] {logging_mixin.py:104} INFO - Running <TaskInstance: my_elastic_search_dag.CheckElasticSearchConnexion 2022-12-05T00:00:00+00:00 [running]> on host dca14bec1869
[2022-12-06 08:17:42,793] {taskinstance.py:1302} INFO - Exporting the following env vars:
AIRFLOW_CTX_DAG_OWNER=***
AIRFLOW_CTX_DAG_ID=my_elastic_search_dag
AIRFLOW_CTX_TASK_ID=CheckElasticSearchConnexion
AIRFLOW_CTX_EXECUTION_DATE=2022-12-05T00:00:00+00:00
AIRFLOW_CTX_DAG_RUN_ID=scheduled__2022-12-05T00:00:00+00:00
[2022-12-06 08:17:42,794] {logging_mixin.py:104} INFO - 50
[2022-12-06 08:17:42,794] {taskinstance.py:1501} ERROR - Task failed with exception
Traceback (most recent call last):
  File "/home/airflow/.local/lib/python3.6/site-packages/airflow/models/taskinstance.py", line 1157, in _run_raw_task
    self._prepare_and_execute_task_with_callbacks(context, task)
  File "/home/airflow/.local/lib/python3.6/site-packages/airflow/models/taskinstance.py", line 1331, in _prepare_and_execute_task_with_callbacks
    result = self._execute_task(context, task_copy)
  File "/home/airflow/.local/lib/python3.6/site-packages/airflow/models/taskinstance.py", line 1361, in _execute_task
    result = task_copy.execute(context=context)
  File "/home/airflow/.local/lib/python3.6/site-packages/airflow/operators/python.py", line 150, in execute
    return_value = self.execute_callable()
  File "/home/airflow/.local/lib/python3.6/site-packages/airflow/operators/python.py", line 161, in execute_callable
    return self.python_callable(*self.op_args, **self.op_kwargs)
  File "/opt/airflow/dags/my_elastic_search_dag.py", line 29, in random_fail_task
    raise Exception('This task randomly failed')
Exception: This task randomly failed
[2022-12-06 08:17:42,795] {taskinstance.py:1551} INFO - Marking task as UP_FOR_RETRY. dag_id=my_elastic_search_dag, task_id=CheckElasticSearchConnexion, execution_date=20221205T000000, start_date=20221206T081742, end_date=20221206T081742
[2022-12-06 08:17:42,850] {local_task_job.py:151} INFO - Task exited with return code 1
[2022-12-06 09:11:36,038] {taskinstance.py:896} INFO - Dependencies all met for <TaskInstance: my_elastic_search_dag.CheckElasticSearchConnexion 2022-12-05T00:00:00+00:00 [queued]>
[2022-12-06 09:11:36,052] {taskinstance.py:896} INFO - Dependencies all met for <TaskInstance: my_elastic_search_dag.CheckElasticSearchConnexion 2022-12-05T00:00:00+00:00 [queued]>
[2022-12-06 09:11:36,052] {taskinstance.py:1087} INFO - 
--------------------------------------------------------------------------------
[2022-12-06 09:11:36,052] {taskinstance.py:1088} INFO - Starting attempt 2 of 51
[2022-12-06 09:11:36,052] {taskinstance.py:1089} INFO - 
--------------------------------------------------------------------------------
[2022-12-06 09:11:36,058] {taskinstance.py:1107} INFO - Executing <Task(PythonOperator): CheckElasticSearchConnexion> on 2022-12-05T00:00:00+00:00
[2022-12-06 09:11:36,062] {standard_task_runner.py:52} INFO - Started process 577 to run task
[2022-12-06 09:11:36,065] {standard_task_runner.py:76} INFO - Running: ['***', 'tasks', 'run', 'my_elastic_search_dag', 'CheckElasticSearchConnexion', '2022-12-05T00:00:00+00:00', '--job-id', '4', '--pool', 'default_pool', '--raw', '--subdir', 'DAGS_FOLDER/my_elastic_search_dag.py', '--cfg-path', '/tmp/tmp1fg7zx0q', '--error-file', '/tmp/tmp3euz16d8']
[2022-12-06 09:11:36,066] {standard_task_runner.py:77} INFO - Job 4: Subtask CheckElasticSearchConnexion
[2022-12-06 09:11:36,101] {logging_mixin.py:104} INFO - Running <TaskInstance: my_elastic_search_dag.CheckElasticSearchConnexion 2022-12-05T00:00:00+00:00 [running]> on host 27e998575b9f
[2022-12-06 09:11:36,139] {taskinstance.py:1302} INFO - Exporting the following env vars:
AIRFLOW_CTX_DAG_OWNER=***
AIRFLOW_CTX_DAG_ID=my_elastic_search_dag
AIRFLOW_CTX_TASK_ID=CheckElasticSearchConnexion
AIRFLOW_CTX_EXECUTION_DATE=2022-12-05T00:00:00+00:00
AIRFLOW_CTX_DAG_RUN_ID=scheduled__2022-12-05T00:00:00+00:00
[2022-12-06 09:11:36,140] {logging_mixin.py:104} INFO - 23
[2022-12-06 09:11:36,140] {taskinstance.py:1501} ERROR - Task failed with exception
Traceback (most recent call last):
  File "/home/airflow/.local/lib/python3.6/site-packages/airflow/models/taskinstance.py", line 1157, in _run_raw_task
    self._prepare_and_execute_task_with_callbacks(context, task)
  File "/home/airflow/.local/lib/python3.6/site-packages/airflow/models/taskinstance.py", line 1331, in _prepare_and_execute_task_with_callbacks
    result = self._execute_task(context, task_copy)
  File "/home/airflow/.local/lib/python3.6/site-packages/airflow/models/taskinstance.py", line 1361, in _execute_task
    result = task_copy.execute(context=context)
  File "/home/airflow/.local/lib/python3.6/site-packages/airflow/operators/python.py", line 150, in execute
    return_value = self.execute_callable()
  File "/home/airflow/.local/lib/python3.6/site-packages/airflow/operators/python.py", line 161, in execute_callable
    return self.python_callable(*self.op_args, **self.op_kwargs)
  File "/opt/airflow/dags/my_elastic_search_dag.py", line 29, in random_fail_task
    raise Exception('This task randomly failed')
Exception: This task randomly failed
[2022-12-06 09:11:36,141] {taskinstance.py:1551} INFO - Marking task as UP_FOR_RETRY. dag_id=my_elastic_search_dag, task_id=CheckElasticSearchConnexion, execution_date=20221205T000000, start_date=20221206T091136, end_date=20221206T091136
[2022-12-06 09:11:36,159] {local_task_job.py:151} INFO - Task exited with return code 1
[2022-12-06 09:18:22,426] {taskinstance.py:896} INFO - Dependencies all met for <TaskInstance: my_elastic_search_dag.CheckElasticSearchConnexion 2022-12-05T00:00:00+00:00 [queued]>
[2022-12-06 09:18:22,438] {taskinstance.py:896} INFO - Dependencies all met for <TaskInstance: my_elastic_search_dag.CheckElasticSearchConnexion 2022-12-05T00:00:00+00:00 [queued]>
[2022-12-06 09:18:22,439] {taskinstance.py:1087} INFO - 
--------------------------------------------------------------------------------
[2022-12-06 09:18:22,439] {taskinstance.py:1088} INFO - Starting attempt 2 of 51
[2022-12-06 09:18:22,439] {taskinstance.py:1089} INFO - 
--------------------------------------------------------------------------------
[2022-12-06 09:18:22,445] {taskinstance.py:1107} INFO - Executing <Task(PythonOperator): CheckElasticSearchConnexion> on 2022-12-05T00:00:00+00:00
[2022-12-06 09:18:22,448] {standard_task_runner.py:52} INFO - Started process 1159 to run task
[2022-12-06 09:18:22,452] {standard_task_runner.py:76} INFO - Running: ['***', 'tasks', 'run', 'my_elastic_search_dag', 'CheckElasticSearchConnexion', '2022-12-05T00:00:00+00:00', '--job-id', '23', '--pool', 'default_pool', '--raw', '--subdir', 'DAGS_FOLDER/my_elastic_search_dag.py', '--cfg-path', '/tmp/tmpnmfuskfq', '--error-file', '/tmp/tmpuvsvdsnk']
[2022-12-06 09:18:22,452] {standard_task_runner.py:77} INFO - Job 23: Subtask CheckElasticSearchConnexion
[2022-12-06 09:18:22,489] {logging_mixin.py:104} INFO - Running <TaskInstance: my_elastic_search_dag.CheckElasticSearchConnexion 2022-12-05T00:00:00+00:00 [running]> on host 27e998575b9f
[2022-12-06 09:18:22,529] {taskinstance.py:1302} INFO - Exporting the following env vars:
AIRFLOW_CTX_DAG_OWNER=***
AIRFLOW_CTX_DAG_ID=my_elastic_search_dag
AIRFLOW_CTX_TASK_ID=CheckElasticSearchConnexion
AIRFLOW_CTX_EXECUTION_DATE=2022-12-05T00:00:00+00:00
AIRFLOW_CTX_DAG_RUN_ID=scheduled__2022-12-05T00:00:00+00:00
[2022-12-06 09:18:22,530] {logging_mixin.py:104} INFO - 87
[2022-12-06 09:18:22,530] {taskinstance.py:1501} ERROR - Task failed with exception
Traceback (most recent call last):
  File "/home/airflow/.local/lib/python3.6/site-packages/airflow/models/taskinstance.py", line 1157, in _run_raw_task
    self._prepare_and_execute_task_with_callbacks(context, task)
  File "/home/airflow/.local/lib/python3.6/site-packages/airflow/models/taskinstance.py", line 1331, in _prepare_and_execute_task_with_callbacks
    result = self._execute_task(context, task_copy)
  File "/home/airflow/.local/lib/python3.6/site-packages/airflow/models/taskinstance.py", line 1361, in _execute_task
    result = task_copy.execute(context=context)
  File "/home/airflow/.local/lib/python3.6/site-packages/airflow/operators/python.py", line 150, in execute
    return_value = self.execute_callable()
  File "/home/airflow/.local/lib/python3.6/site-packages/airflow/operators/python.py", line 161, in execute_callable
    return self.python_callable(*self.op_args, **self.op_kwargs)
  File "/opt/airflow/dags/my_elastic_search_dag.py", line 29, in random_fail_task
    raise Exception('This task randomly failed')
Exception: This task randomly failed
[2022-12-06 09:18:22,531] {taskinstance.py:1551} INFO - Marking task as UP_FOR_RETRY. dag_id=my_elastic_search_dag, task_id=CheckElasticSearchConnexion, execution_date=20221205T000000, start_date=20221206T091822, end_date=20221206T091822
[2022-12-06 09:18:22,586] {local_task_job.py:151} INFO - Task exited with return code 1
[2022-12-06 09:53:12,995] {taskinstance.py:896} INFO - Dependencies all met for <TaskInstance: my_elastic_search_dag.CheckElasticSearchConnexion 2022-12-05T00:00:00+00:00 [queued]>
[2022-12-06 09:53:13,012] {taskinstance.py:896} INFO - Dependencies all met for <TaskInstance: my_elastic_search_dag.CheckElasticSearchConnexion 2022-12-05T00:00:00+00:00 [queued]>
[2022-12-06 09:53:13,012] {taskinstance.py:1087} INFO - 
--------------------------------------------------------------------------------
[2022-12-06 09:53:13,012] {taskinstance.py:1088} INFO - Starting attempt 2 of 51
[2022-12-06 09:53:13,012] {taskinstance.py:1089} INFO - 
--------------------------------------------------------------------------------
[2022-12-06 09:53:13,021] {taskinstance.py:1107} INFO - Executing <Task(PythonOperator): CheckElasticSearchConnexion> on 2022-12-05T00:00:00+00:00
[2022-12-06 09:53:13,029] {standard_task_runner.py:76} INFO - Running: ['***', 'tasks', 'run', 'my_elastic_search_dag', 'CheckElasticSearchConnexion', '2022-12-05T00:00:00+00:00', '--job-id', '4', '--pool', 'default_pool', '--raw', '--subdir', 'DAGS_FOLDER/my_elastic_search_dag.py', '--cfg-path', '/tmp/tmpanywa1jf', '--error-file', '/tmp/tmpbvrscke1']
[2022-12-06 09:53:13,025] {standard_task_runner.py:52} INFO - Started process 222 to run task
[2022-12-06 09:53:13,029] {standard_task_runner.py:77} INFO - Job 4: Subtask CheckElasticSearchConnexion
[2022-12-06 09:53:13,070] {logging_mixin.py:104} INFO - Running <TaskInstance: my_elastic_search_dag.CheckElasticSearchConnexion 2022-12-05T00:00:00+00:00 [running]> on host 4467c39e9c9a
[2022-12-06 09:53:13,121] {taskinstance.py:1302} INFO - Exporting the following env vars:
AIRFLOW_CTX_DAG_OWNER=***
AIRFLOW_CTX_DAG_ID=my_elastic_search_dag
AIRFLOW_CTX_TASK_ID=CheckElasticSearchConnexion
AIRFLOW_CTX_EXECUTION_DATE=2022-12-05T00:00:00+00:00
AIRFLOW_CTX_DAG_RUN_ID=scheduled__2022-12-05T00:00:00+00:00
[2022-12-06 09:53:13,122] {logging_mixin.py:104} INFO - 5
[2022-12-06 09:53:13,122] {python.py:151} INFO - Done. Returned value was: None
[2022-12-06 09:53:13,133] {taskinstance.py:1211} INFO - Marking task as SUCCESS. dag_id=my_elastic_search_dag, task_id=CheckElasticSearchConnexion, execution_date=20221205T000000, start_date=20221206T095312, end_date=20221206T095313
[2022-12-06 09:53:13,168] {taskinstance.py:1265} INFO - 2 downstream tasks scheduled from follow-on schedule check
[2022-12-06 09:53:13,203] {local_task_job.py:151} INFO - Task exited with return code 0
[2022-12-06 10:00:37,116] {taskinstance.py:896} INFO - Dependencies all met for <TaskInstance: my_elastic_search_dag.CheckElasticSearchConnexion 2022-12-05T00:00:00+00:00 [queued]>
[2022-12-06 10:00:37,129] {taskinstance.py:896} INFO - Dependencies all met for <TaskInstance: my_elastic_search_dag.CheckElasticSearchConnexion 2022-12-05T00:00:00+00:00 [queued]>
[2022-12-06 10:00:37,130] {taskinstance.py:1087} INFO - 
--------------------------------------------------------------------------------
[2022-12-06 10:00:37,130] {taskinstance.py:1088} INFO - Starting attempt 2 of 51
[2022-12-06 10:00:37,130] {taskinstance.py:1089} INFO - 
--------------------------------------------------------------------------------
[2022-12-06 10:00:37,143] {taskinstance.py:1107} INFO - Executing <Task(PythonOperator): CheckElasticSearchConnexion> on 2022-12-05T00:00:00+00:00
[2022-12-06 10:00:37,147] {standard_task_runner.py:52} INFO - Started process 338 to run task
[2022-12-06 10:00:37,151] {standard_task_runner.py:76} INFO - Running: ['***', 'tasks', 'run', 'my_elastic_search_dag', 'CheckElasticSearchConnexion', '2022-12-05T00:00:00+00:00', '--job-id', '6', '--pool', 'default_pool', '--raw', '--subdir', 'DAGS_FOLDER/my_elastic_search_dag.py', '--cfg-path', '/tmp/tmprs_cw1e5', '--error-file', '/tmp/tmpnmuanudz']
[2022-12-06 10:00:37,151] {standard_task_runner.py:77} INFO - Job 6: Subtask CheckElasticSearchConnexion
[2022-12-06 10:00:37,199] {logging_mixin.py:104} INFO - Running <TaskInstance: my_elastic_search_dag.CheckElasticSearchConnexion 2022-12-05T00:00:00+00:00 [running]> on host 3d95da7470fe
[2022-12-06 10:00:37,251] {taskinstance.py:1302} INFO - Exporting the following env vars:
AIRFLOW_CTX_DAG_OWNER=***
AIRFLOW_CTX_DAG_ID=my_elastic_search_dag
AIRFLOW_CTX_TASK_ID=CheckElasticSearchConnexion
AIRFLOW_CTX_EXECUTION_DATE=2022-12-05T00:00:00+00:00
AIRFLOW_CTX_DAG_RUN_ID=scheduled__2022-12-05T00:00:00+00:00
[2022-12-06 10:00:37,252] {logging_mixin.py:104} INFO - 41
[2022-12-06 10:00:37,252] {taskinstance.py:1501} ERROR - Task failed with exception
Traceback (most recent call last):
  File "/home/airflow/.local/lib/python3.6/site-packages/airflow/models/taskinstance.py", line 1157, in _run_raw_task
    self._prepare_and_execute_task_with_callbacks(context, task)
  File "/home/airflow/.local/lib/python3.6/site-packages/airflow/models/taskinstance.py", line 1331, in _prepare_and_execute_task_with_callbacks
    result = self._execute_task(context, task_copy)
  File "/home/airflow/.local/lib/python3.6/site-packages/airflow/models/taskinstance.py", line 1361, in _execute_task
    result = task_copy.execute(context=context)
  File "/home/airflow/.local/lib/python3.6/site-packages/airflow/operators/python.py", line 150, in execute
    return_value = self.execute_callable()
  File "/home/airflow/.local/lib/python3.6/site-packages/airflow/operators/python.py", line 161, in execute_callable
    return self.python_callable(*self.op_args, **self.op_kwargs)
  File "/opt/airflow/dags/my_elastic_search_dag.py", line 29, in random_fail_task
    raise Exception('This task randomly failed')
Exception: This task randomly failed
[2022-12-06 10:00:37,254] {taskinstance.py:1551} INFO - Marking task as UP_FOR_RETRY. dag_id=my_elastic_search_dag, task_id=CheckElasticSearchConnexion, execution_date=20221205T000000, start_date=20221206T100037, end_date=20221206T100037
[2022-12-06 10:00:37,285] {local_task_job.py:151} INFO - Task exited with return code 1
[2022-12-06 10:20:13,102] {taskinstance.py:896} INFO - Dependencies all met for <TaskInstance: my_elastic_search_dag.CheckElasticSearchConnexion 2022-12-05T00:00:00+00:00 [queued]>
[2022-12-06 10:20:13,121] {taskinstance.py:896} INFO - Dependencies all met for <TaskInstance: my_elastic_search_dag.CheckElasticSearchConnexion 2022-12-05T00:00:00+00:00 [queued]>
[2022-12-06 10:20:13,121] {taskinstance.py:1087} INFO - 
--------------------------------------------------------------------------------
[2022-12-06 10:20:13,122] {taskinstance.py:1088} INFO - Starting attempt 2 of 51
[2022-12-06 10:20:13,122] {taskinstance.py:1089} INFO - 
--------------------------------------------------------------------------------
[2022-12-06 10:20:13,133] {taskinstance.py:1107} INFO - Executing <Task(PythonOperator): CheckElasticSearchConnexion> on 2022-12-05T00:00:00+00:00
[2022-12-06 10:20:13,137] {standard_task_runner.py:52} INFO - Started process 238 to run task
[2022-12-06 10:20:13,142] {standard_task_runner.py:76} INFO - Running: ['***', 'tasks', 'run', 'my_elastic_search_dag', 'CheckElasticSearchConnexion', '2022-12-05T00:00:00+00:00', '--job-id', '3', '--pool', 'default_pool', '--raw', '--subdir', 'DAGS_FOLDER/my_elastic_search_dag.py', '--cfg-path', '/tmp/tmpr3v6zg7h', '--error-file', '/tmp/tmp959yul2h']
[2022-12-06 10:20:13,142] {standard_task_runner.py:77} INFO - Job 3: Subtask CheckElasticSearchConnexion
[2022-12-06 10:20:13,201] {logging_mixin.py:104} INFO - Running <TaskInstance: my_elastic_search_dag.CheckElasticSearchConnexion 2022-12-05T00:00:00+00:00 [running]> on host 33da1fe70ee2
[2022-12-06 10:20:13,273] {taskinstance.py:1302} INFO - Exporting the following env vars:
AIRFLOW_CTX_DAG_OWNER=***
AIRFLOW_CTX_DAG_ID=my_elastic_search_dag
AIRFLOW_CTX_TASK_ID=CheckElasticSearchConnexion
AIRFLOW_CTX_EXECUTION_DATE=2022-12-05T00:00:00+00:00
AIRFLOW_CTX_DAG_RUN_ID=scheduled__2022-12-05T00:00:00+00:00
[2022-12-06 10:20:13,274] {logging_mixin.py:104} INFO - 68
[2022-12-06 10:20:13,274] {taskinstance.py:1501} ERROR - Task failed with exception
Traceback (most recent call last):
  File "/home/airflow/.local/lib/python3.6/site-packages/airflow/models/taskinstance.py", line 1157, in _run_raw_task
    self._prepare_and_execute_task_with_callbacks(context, task)
  File "/home/airflow/.local/lib/python3.6/site-packages/airflow/models/taskinstance.py", line 1331, in _prepare_and_execute_task_with_callbacks
    result = self._execute_task(context, task_copy)
  File "/home/airflow/.local/lib/python3.6/site-packages/airflow/models/taskinstance.py", line 1361, in _execute_task
    result = task_copy.execute(context=context)
  File "/home/airflow/.local/lib/python3.6/site-packages/airflow/operators/python.py", line 150, in execute
    return_value = self.execute_callable()
  File "/home/airflow/.local/lib/python3.6/site-packages/airflow/operators/python.py", line 161, in execute_callable
    return self.python_callable(*self.op_args, **self.op_kwargs)
  File "/opt/airflow/dags/my_elastic_search_dag.py", line 29, in random_fail_task
    raise Exception('This task randomly failed')
Exception: This task randomly failed
[2022-12-06 10:20:13,277] {taskinstance.py:1551} INFO - Marking task as UP_FOR_RETRY. dag_id=my_elastic_search_dag, task_id=CheckElasticSearchConnexion, execution_date=20221205T000000, start_date=20221206T102013, end_date=20221206T102013
[2022-12-06 10:20:13,324] {local_task_job.py:151} INFO - Task exited with return code 1
