[2022-12-06 08:17:48,860] {taskinstance.py:896} INFO - Dependencies all met for <TaskInstance: my_elastic_search_dag.CheckElasticSearchConnexion 2022-12-05T00:00:00+00:00 [queued]>
[2022-12-06 08:17:48,876] {taskinstance.py:896} INFO - Dependencies all met for <TaskInstance: my_elastic_search_dag.CheckElasticSearchConnexion 2022-12-05T00:00:00+00:00 [queued]>
[2022-12-06 08:17:48,876] {taskinstance.py:1087} INFO - 
--------------------------------------------------------------------------------
[2022-12-06 08:17:48,876] {taskinstance.py:1088} INFO - Starting attempt 3 of 51
[2022-12-06 08:17:48,876] {taskinstance.py:1089} INFO - 
--------------------------------------------------------------------------------
[2022-12-06 08:17:48,889] {taskinstance.py:1107} INFO - Executing <Task(PythonOperator): CheckElasticSearchConnexion> on 2022-12-05T00:00:00+00:00
[2022-12-06 08:17:48,893] {standard_task_runner.py:52} INFO - Started process 319 to run task
[2022-12-06 08:17:48,899] {standard_task_runner.py:76} INFO - Running: ['***', 'tasks', 'run', 'my_elastic_search_dag', 'CheckElasticSearchConnexion', '2022-12-05T00:00:00+00:00', '--job-id', '6', '--pool', 'default_pool', '--raw', '--subdir', 'DAGS_FOLDER/my_elastic_search_dag.py', '--cfg-path', '/tmp/tmp3sgkq_7w', '--error-file', '/tmp/tmpu8by5rzv']
[2022-12-06 08:17:48,899] {standard_task_runner.py:77} INFO - Job 6: Subtask CheckElasticSearchConnexion
[2022-12-06 08:17:49,005] {logging_mixin.py:104} INFO - Running <TaskInstance: my_elastic_search_dag.CheckElasticSearchConnexion 2022-12-05T00:00:00+00:00 [running]> on host dca14bec1869
[2022-12-06 08:17:49,063] {taskinstance.py:1302} INFO - Exporting the following env vars:
AIRFLOW_CTX_DAG_OWNER=***
AIRFLOW_CTX_DAG_ID=my_elastic_search_dag
AIRFLOW_CTX_TASK_ID=CheckElasticSearchConnexion
AIRFLOW_CTX_EXECUTION_DATE=2022-12-05T00:00:00+00:00
AIRFLOW_CTX_DAG_RUN_ID=scheduled__2022-12-05T00:00:00+00:00
[2022-12-06 08:17:49,064] {logging_mixin.py:104} INFO - 39
[2022-12-06 08:17:49,064] {taskinstance.py:1501} ERROR - Task failed with exception
Traceback (most recent call last):
  File "/home/airflow/.local/lib/python3.6/site-packages/airflow/models/taskinstance.py", line 1157, in _run_raw_task
    self._prepare_and_execute_task_with_callbacks(context, task)
  File "/home/airflow/.local/lib/python3.6/site-packages/airflow/models/taskinstance.py", line 1331, in _prepare_and_execute_task_with_callbacks
    result = self._execute_task(context, task_copy)
  File "/home/airflow/.local/lib/python3.6/site-packages/airflow/models/taskinstance.py", line 1361, in _execute_task
    result = task_copy.execute(context=context)
  File "/home/airflow/.local/lib/python3.6/site-packages/airflow/operators/python.py", line 150, in execute
    return_value = self.execute_callable()
  File "/home/airflow/.local/lib/python3.6/site-packages/airflow/operators/python.py", line 161, in execute_callable
    return self.python_callable(*self.op_args, **self.op_kwargs)
  File "/opt/airflow/dags/my_elastic_search_dag.py", line 29, in random_fail_task
    raise Exception('This task randomly failed')
Exception: This task randomly failed
[2022-12-06 08:17:49,066] {taskinstance.py:1551} INFO - Marking task as UP_FOR_RETRY. dag_id=my_elastic_search_dag, task_id=CheckElasticSearchConnexion, execution_date=20221205T000000, start_date=20221206T081748, end_date=20221206T081749
[2022-12-06 08:17:49,113] {local_task_job.py:151} INFO - Task exited with return code 1
[2022-12-06 09:11:41,595] {taskinstance.py:896} INFO - Dependencies all met for <TaskInstance: my_elastic_search_dag.CheckElasticSearchConnexion 2022-12-05T00:00:00+00:00 [queued]>
[2022-12-06 09:11:41,612] {taskinstance.py:896} INFO - Dependencies all met for <TaskInstance: my_elastic_search_dag.CheckElasticSearchConnexion 2022-12-05T00:00:00+00:00 [queued]>
[2022-12-06 09:11:41,612] {taskinstance.py:1087} INFO - 
--------------------------------------------------------------------------------
[2022-12-06 09:11:41,612] {taskinstance.py:1088} INFO - Starting attempt 3 of 51
[2022-12-06 09:11:41,612] {taskinstance.py:1089} INFO - 
--------------------------------------------------------------------------------
[2022-12-06 09:11:41,625] {taskinstance.py:1107} INFO - Executing <Task(PythonOperator): CheckElasticSearchConnexion> on 2022-12-05T00:00:00+00:00
[2022-12-06 09:11:41,633] {standard_task_runner.py:76} INFO - Running: ['***', 'tasks', 'run', 'my_elastic_search_dag', 'CheckElasticSearchConnexion', '2022-12-05T00:00:00+00:00', '--job-id', '6', '--pool', 'default_pool', '--raw', '--subdir', 'DAGS_FOLDER/my_elastic_search_dag.py', '--cfg-path', '/tmp/tmpnruppz7x', '--error-file', '/tmp/tmpsbmpwxj1']
[2022-12-06 09:11:41,628] {standard_task_runner.py:52} INFO - Started process 591 to run task
[2022-12-06 09:11:41,633] {standard_task_runner.py:77} INFO - Job 6: Subtask CheckElasticSearchConnexion
[2022-12-06 09:11:41,710] {logging_mixin.py:104} INFO - Running <TaskInstance: my_elastic_search_dag.CheckElasticSearchConnexion 2022-12-05T00:00:00+00:00 [running]> on host 27e998575b9f
[2022-12-06 09:11:41,924] {taskinstance.py:1302} INFO - Exporting the following env vars:
AIRFLOW_CTX_DAG_OWNER=***
AIRFLOW_CTX_DAG_ID=my_elastic_search_dag
AIRFLOW_CTX_TASK_ID=CheckElasticSearchConnexion
AIRFLOW_CTX_EXECUTION_DATE=2022-12-05T00:00:00+00:00
AIRFLOW_CTX_DAG_RUN_ID=scheduled__2022-12-05T00:00:00+00:00
[2022-12-06 09:11:41,925] {logging_mixin.py:104} INFO - 91
[2022-12-06 09:11:41,926] {taskinstance.py:1501} ERROR - Task failed with exception
Traceback (most recent call last):
  File "/home/airflow/.local/lib/python3.6/site-packages/airflow/models/taskinstance.py", line 1157, in _run_raw_task
    self._prepare_and_execute_task_with_callbacks(context, task)
  File "/home/airflow/.local/lib/python3.6/site-packages/airflow/models/taskinstance.py", line 1331, in _prepare_and_execute_task_with_callbacks
    result = self._execute_task(context, task_copy)
  File "/home/airflow/.local/lib/python3.6/site-packages/airflow/models/taskinstance.py", line 1361, in _execute_task
    result = task_copy.execute(context=context)
  File "/home/airflow/.local/lib/python3.6/site-packages/airflow/operators/python.py", line 150, in execute
    return_value = self.execute_callable()
  File "/home/airflow/.local/lib/python3.6/site-packages/airflow/operators/python.py", line 161, in execute_callable
    return self.python_callable(*self.op_args, **self.op_kwargs)
  File "/opt/airflow/dags/my_elastic_search_dag.py", line 29, in random_fail_task
    raise Exception('This task randomly failed')
Exception: This task randomly failed
[2022-12-06 09:11:41,929] {taskinstance.py:1551} INFO - Marking task as UP_FOR_RETRY. dag_id=my_elastic_search_dag, task_id=CheckElasticSearchConnexion, execution_date=20221205T000000, start_date=20221206T091141, end_date=20221206T091141
[2022-12-06 09:11:42,055] {local_task_job.py:151} INFO - Task exited with return code 1
[2022-12-06 09:18:28,002] {taskinstance.py:896} INFO - Dependencies all met for <TaskInstance: my_elastic_search_dag.CheckElasticSearchConnexion 2022-12-05T00:00:00+00:00 [queued]>
[2022-12-06 09:18:28,015] {taskinstance.py:896} INFO - Dependencies all met for <TaskInstance: my_elastic_search_dag.CheckElasticSearchConnexion 2022-12-05T00:00:00+00:00 [queued]>
[2022-12-06 09:18:28,015] {taskinstance.py:1087} INFO - 
--------------------------------------------------------------------------------
[2022-12-06 09:18:28,015] {taskinstance.py:1088} INFO - Starting attempt 3 of 51
[2022-12-06 09:18:28,015] {taskinstance.py:1089} INFO - 
--------------------------------------------------------------------------------
[2022-12-06 09:18:28,022] {taskinstance.py:1107} INFO - Executing <Task(PythonOperator): CheckElasticSearchConnexion> on 2022-12-05T00:00:00+00:00
[2022-12-06 09:18:28,025] {standard_task_runner.py:52} INFO - Started process 1163 to run task
[2022-12-06 09:18:28,029] {standard_task_runner.py:76} INFO - Running: ['***', 'tasks', 'run', 'my_elastic_search_dag', 'CheckElasticSearchConnexion', '2022-12-05T00:00:00+00:00', '--job-id', '25', '--pool', 'default_pool', '--raw', '--subdir', 'DAGS_FOLDER/my_elastic_search_dag.py', '--cfg-path', '/tmp/tmpbs94n54s', '--error-file', '/tmp/tmpxbzq4l9n']
[2022-12-06 09:18:28,029] {standard_task_runner.py:77} INFO - Job 25: Subtask CheckElasticSearchConnexion
[2022-12-06 09:18:28,065] {logging_mixin.py:104} INFO - Running <TaskInstance: my_elastic_search_dag.CheckElasticSearchConnexion 2022-12-05T00:00:00+00:00 [running]> on host 27e998575b9f
[2022-12-06 09:18:28,104] {taskinstance.py:1302} INFO - Exporting the following env vars:
AIRFLOW_CTX_DAG_OWNER=***
AIRFLOW_CTX_DAG_ID=my_elastic_search_dag
AIRFLOW_CTX_TASK_ID=CheckElasticSearchConnexion
AIRFLOW_CTX_EXECUTION_DATE=2022-12-05T00:00:00+00:00
AIRFLOW_CTX_DAG_RUN_ID=scheduled__2022-12-05T00:00:00+00:00
[2022-12-06 09:18:28,104] {logging_mixin.py:104} INFO - 4
[2022-12-06 09:18:28,105] {python.py:151} INFO - Done. Returned value was: None
[2022-12-06 09:18:28,114] {taskinstance.py:1211} INFO - Marking task as SUCCESS. dag_id=my_elastic_search_dag, task_id=CheckElasticSearchConnexion, execution_date=20221205T000000, start_date=20221206T091828, end_date=20221206T091828
[2022-12-06 09:18:28,142] {taskinstance.py:1265} INFO - 2 downstream tasks scheduled from follow-on schedule check
[2022-12-06 09:18:28,163] {local_task_job.py:151} INFO - Task exited with return code 0
[2022-12-06 10:00:42,881] {taskinstance.py:896} INFO - Dependencies all met for <TaskInstance: my_elastic_search_dag.CheckElasticSearchConnexion 2022-12-05T00:00:00+00:00 [queued]>
[2022-12-06 10:00:42,890] {taskinstance.py:896} INFO - Dependencies all met for <TaskInstance: my_elastic_search_dag.CheckElasticSearchConnexion 2022-12-05T00:00:00+00:00 [queued]>
[2022-12-06 10:00:42,890] {taskinstance.py:1087} INFO - 
--------------------------------------------------------------------------------
[2022-12-06 10:00:42,890] {taskinstance.py:1088} INFO - Starting attempt 3 of 51
[2022-12-06 10:00:42,890] {taskinstance.py:1089} INFO - 
--------------------------------------------------------------------------------
[2022-12-06 10:00:42,901] {taskinstance.py:1107} INFO - Executing <Task(PythonOperator): CheckElasticSearchConnexion> on 2022-12-05T00:00:00+00:00
[2022-12-06 10:00:42,908] {standard_task_runner.py:76} INFO - Running: ['***', 'tasks', 'run', 'my_elastic_search_dag', 'CheckElasticSearchConnexion', '2022-12-05T00:00:00+00:00', '--job-id', '8', '--pool', 'default_pool', '--raw', '--subdir', 'DAGS_FOLDER/my_elastic_search_dag.py', '--cfg-path', '/tmp/tmpszco5h3c', '--error-file', '/tmp/tmp0h7nly71']
[2022-12-06 10:00:42,908] {standard_task_runner.py:77} INFO - Job 8: Subtask CheckElasticSearchConnexion
[2022-12-06 10:00:42,905] {standard_task_runner.py:52} INFO - Started process 349 to run task
[2022-12-06 10:00:42,946] {logging_mixin.py:104} INFO - Running <TaskInstance: my_elastic_search_dag.CheckElasticSearchConnexion 2022-12-05T00:00:00+00:00 [running]> on host 3d95da7470fe
[2022-12-06 10:00:42,987] {taskinstance.py:1302} INFO - Exporting the following env vars:
AIRFLOW_CTX_DAG_OWNER=***
AIRFLOW_CTX_DAG_ID=my_elastic_search_dag
AIRFLOW_CTX_TASK_ID=CheckElasticSearchConnexion
AIRFLOW_CTX_EXECUTION_DATE=2022-12-05T00:00:00+00:00
AIRFLOW_CTX_DAG_RUN_ID=scheduled__2022-12-05T00:00:00+00:00
[2022-12-06 10:00:42,988] {logging_mixin.py:104} INFO - 26
[2022-12-06 10:00:42,988] {taskinstance.py:1501} ERROR - Task failed with exception
Traceback (most recent call last):
  File "/home/airflow/.local/lib/python3.6/site-packages/airflow/models/taskinstance.py", line 1157, in _run_raw_task
    self._prepare_and_execute_task_with_callbacks(context, task)
  File "/home/airflow/.local/lib/python3.6/site-packages/airflow/models/taskinstance.py", line 1331, in _prepare_and_execute_task_with_callbacks
    result = self._execute_task(context, task_copy)
  File "/home/airflow/.local/lib/python3.6/site-packages/airflow/models/taskinstance.py", line 1361, in _execute_task
    result = task_copy.execute(context=context)
  File "/home/airflow/.local/lib/python3.6/site-packages/airflow/operators/python.py", line 150, in execute
    return_value = self.execute_callable()
  File "/home/airflow/.local/lib/python3.6/site-packages/airflow/operators/python.py", line 161, in execute_callable
    return self.python_callable(*self.op_args, **self.op_kwargs)
  File "/opt/airflow/dags/my_elastic_search_dag.py", line 29, in random_fail_task
    raise Exception('This task randomly failed')
Exception: This task randomly failed
[2022-12-06 10:00:42,989] {taskinstance.py:1551} INFO - Marking task as UP_FOR_RETRY. dag_id=my_elastic_search_dag, task_id=CheckElasticSearchConnexion, execution_date=20221205T000000, start_date=20221206T100042, end_date=20221206T100042
[2022-12-06 10:00:43,043] {local_task_job.py:151} INFO - Task exited with return code 1
[2022-12-06 10:20:19,455] {taskinstance.py:896} INFO - Dependencies all met for <TaskInstance: my_elastic_search_dag.CheckElasticSearchConnexion 2022-12-05T00:00:00+00:00 [queued]>
[2022-12-06 10:20:19,474] {taskinstance.py:896} INFO - Dependencies all met for <TaskInstance: my_elastic_search_dag.CheckElasticSearchConnexion 2022-12-05T00:00:00+00:00 [queued]>
[2022-12-06 10:20:19,474] {taskinstance.py:1087} INFO - 
--------------------------------------------------------------------------------
[2022-12-06 10:20:19,475] {taskinstance.py:1088} INFO - Starting attempt 3 of 51
[2022-12-06 10:20:19,475] {taskinstance.py:1089} INFO - 
--------------------------------------------------------------------------------
[2022-12-06 10:20:19,486] {taskinstance.py:1107} INFO - Executing <Task(PythonOperator): CheckElasticSearchConnexion> on 2022-12-05T00:00:00+00:00
[2022-12-06 10:20:19,496] {standard_task_runner.py:76} INFO - Running: ['***', 'tasks', 'run', 'my_elastic_search_dag', 'CheckElasticSearchConnexion', '2022-12-05T00:00:00+00:00', '--job-id', '4', '--pool', 'default_pool', '--raw', '--subdir', 'DAGS_FOLDER/my_elastic_search_dag.py', '--cfg-path', '/tmp/tmpohi8tu9b', '--error-file', '/tmp/tmphas8djss']
[2022-12-06 10:20:19,491] {standard_task_runner.py:52} INFO - Started process 240 to run task
[2022-12-06 10:20:19,497] {standard_task_runner.py:77} INFO - Job 4: Subtask CheckElasticSearchConnexion
[2022-12-06 10:20:19,547] {logging_mixin.py:104} INFO - Running <TaskInstance: my_elastic_search_dag.CheckElasticSearchConnexion 2022-12-05T00:00:00+00:00 [running]> on host 33da1fe70ee2
[2022-12-06 10:20:19,607] {taskinstance.py:1302} INFO - Exporting the following env vars:
AIRFLOW_CTX_DAG_OWNER=***
AIRFLOW_CTX_DAG_ID=my_elastic_search_dag
AIRFLOW_CTX_TASK_ID=CheckElasticSearchConnexion
AIRFLOW_CTX_EXECUTION_DATE=2022-12-05T00:00:00+00:00
AIRFLOW_CTX_DAG_RUN_ID=scheduled__2022-12-05T00:00:00+00:00
[2022-12-06 10:20:19,608] {logging_mixin.py:104} INFO - 41
[2022-12-06 10:20:19,608] {taskinstance.py:1501} ERROR - Task failed with exception
Traceback (most recent call last):
  File "/home/airflow/.local/lib/python3.6/site-packages/airflow/models/taskinstance.py", line 1157, in _run_raw_task
    self._prepare_and_execute_task_with_callbacks(context, task)
  File "/home/airflow/.local/lib/python3.6/site-packages/airflow/models/taskinstance.py", line 1331, in _prepare_and_execute_task_with_callbacks
    result = self._execute_task(context, task_copy)
  File "/home/airflow/.local/lib/python3.6/site-packages/airflow/models/taskinstance.py", line 1361, in _execute_task
    result = task_copy.execute(context=context)
  File "/home/airflow/.local/lib/python3.6/site-packages/airflow/operators/python.py", line 150, in execute
    return_value = self.execute_callable()
  File "/home/airflow/.local/lib/python3.6/site-packages/airflow/operators/python.py", line 161, in execute_callable
    return self.python_callable(*self.op_args, **self.op_kwargs)
  File "/opt/airflow/dags/my_elastic_search_dag.py", line 29, in random_fail_task
    raise Exception('This task randomly failed')
Exception: This task randomly failed
[2022-12-06 10:20:19,610] {taskinstance.py:1551} INFO - Marking task as UP_FOR_RETRY. dag_id=my_elastic_search_dag, task_id=CheckElasticSearchConnexion, execution_date=20221205T000000, start_date=20221206T102019, end_date=20221206T102019
[2022-12-06 10:20:19,671] {local_task_job.py:151} INFO - Task exited with return code 1
