[2022-12-06 08:17:55,494] {taskinstance.py:896} INFO - Dependencies all met for <TaskInstance: my_elastic_search_dag.CheckElasticSearchConnexion 2022-12-05T00:00:00+00:00 [queued]>
[2022-12-06 08:17:55,507] {taskinstance.py:896} INFO - Dependencies all met for <TaskInstance: my_elastic_search_dag.CheckElasticSearchConnexion 2022-12-05T00:00:00+00:00 [queued]>
[2022-12-06 08:17:55,507] {taskinstance.py:1087} INFO - 
--------------------------------------------------------------------------------
[2022-12-06 08:17:55,507] {taskinstance.py:1088} INFO - Starting attempt 4 of 51
[2022-12-06 08:17:55,507] {taskinstance.py:1089} INFO - 
--------------------------------------------------------------------------------
[2022-12-06 08:17:55,514] {taskinstance.py:1107} INFO - Executing <Task(PythonOperator): CheckElasticSearchConnexion> on 2022-12-05T00:00:00+00:00
[2022-12-06 08:17:55,517] {standard_task_runner.py:52} INFO - Started process 330 to run task
[2022-12-06 08:17:55,520] {standard_task_runner.py:76} INFO - Running: ['***', 'tasks', 'run', 'my_elastic_search_dag', 'CheckElasticSearchConnexion', '2022-12-05T00:00:00+00:00', '--job-id', '8', '--pool', 'default_pool', '--raw', '--subdir', 'DAGS_FOLDER/my_elastic_search_dag.py', '--cfg-path', '/tmp/tmpbr785z0p', '--error-file', '/tmp/tmprte9j68j']
[2022-12-06 08:17:55,521] {standard_task_runner.py:77} INFO - Job 8: Subtask CheckElasticSearchConnexion
[2022-12-06 08:17:55,559] {logging_mixin.py:104} INFO - Running <TaskInstance: my_elastic_search_dag.CheckElasticSearchConnexion 2022-12-05T00:00:00+00:00 [running]> on host dca14bec1869
[2022-12-06 08:17:55,603] {taskinstance.py:1302} INFO - Exporting the following env vars:
AIRFLOW_CTX_DAG_OWNER=***
AIRFLOW_CTX_DAG_ID=my_elastic_search_dag
AIRFLOW_CTX_TASK_ID=CheckElasticSearchConnexion
AIRFLOW_CTX_EXECUTION_DATE=2022-12-05T00:00:00+00:00
AIRFLOW_CTX_DAG_RUN_ID=scheduled__2022-12-05T00:00:00+00:00
[2022-12-06 08:17:55,604] {logging_mixin.py:104} INFO - 10
[2022-12-06 08:17:55,604] {python.py:151} INFO - Done. Returned value was: None
[2022-12-06 08:17:55,614] {taskinstance.py:1211} INFO - Marking task as SUCCESS. dag_id=my_elastic_search_dag, task_id=CheckElasticSearchConnexion, execution_date=20221205T000000, start_date=20221206T081755, end_date=20221206T081755
[2022-12-06 08:17:55,640] {taskinstance.py:1265} INFO - 2 downstream tasks scheduled from follow-on schedule check
[2022-12-06 08:17:55,654] {local_task_job.py:151} INFO - Task exited with return code 0
[2022-12-06 09:11:47,887] {taskinstance.py:896} INFO - Dependencies all met for <TaskInstance: my_elastic_search_dag.CheckElasticSearchConnexion 2022-12-05T00:00:00+00:00 [queued]>
[2022-12-06 09:11:47,900] {taskinstance.py:896} INFO - Dependencies all met for <TaskInstance: my_elastic_search_dag.CheckElasticSearchConnexion 2022-12-05T00:00:00+00:00 [queued]>
[2022-12-06 09:11:47,900] {taskinstance.py:1087} INFO - 
--------------------------------------------------------------------------------
[2022-12-06 09:11:47,900] {taskinstance.py:1088} INFO - Starting attempt 4 of 51
[2022-12-06 09:11:47,900] {taskinstance.py:1089} INFO - 
--------------------------------------------------------------------------------
[2022-12-06 09:11:47,907] {taskinstance.py:1107} INFO - Executing <Task(PythonOperator): CheckElasticSearchConnexion> on 2022-12-05T00:00:00+00:00
[2022-12-06 09:11:47,913] {standard_task_runner.py:76} INFO - Running: ['***', 'tasks', 'run', 'my_elastic_search_dag', 'CheckElasticSearchConnexion', '2022-12-05T00:00:00+00:00', '--job-id', '8', '--pool', 'default_pool', '--raw', '--subdir', 'DAGS_FOLDER/my_elastic_search_dag.py', '--cfg-path', '/tmp/tmppmd9sjny', '--error-file', '/tmp/tmpaj2k5_44']
[2022-12-06 09:11:47,914] {standard_task_runner.py:77} INFO - Job 8: Subtask CheckElasticSearchConnexion
[2022-12-06 09:11:47,910] {standard_task_runner.py:52} INFO - Started process 602 to run task
[2022-12-06 09:11:47,949] {logging_mixin.py:104} INFO - Running <TaskInstance: my_elastic_search_dag.CheckElasticSearchConnexion 2022-12-05T00:00:00+00:00 [running]> on host 27e998575b9f
[2022-12-06 09:11:47,989] {taskinstance.py:1302} INFO - Exporting the following env vars:
AIRFLOW_CTX_DAG_OWNER=***
AIRFLOW_CTX_DAG_ID=my_elastic_search_dag
AIRFLOW_CTX_TASK_ID=CheckElasticSearchConnexion
AIRFLOW_CTX_EXECUTION_DATE=2022-12-05T00:00:00+00:00
AIRFLOW_CTX_DAG_RUN_ID=scheduled__2022-12-05T00:00:00+00:00
[2022-12-06 09:11:47,990] {logging_mixin.py:104} INFO - 24
[2022-12-06 09:11:47,990] {taskinstance.py:1501} ERROR - Task failed with exception
Traceback (most recent call last):
  File "/home/airflow/.local/lib/python3.6/site-packages/airflow/models/taskinstance.py", line 1157, in _run_raw_task
    self._prepare_and_execute_task_with_callbacks(context, task)
  File "/home/airflow/.local/lib/python3.6/site-packages/airflow/models/taskinstance.py", line 1331, in _prepare_and_execute_task_with_callbacks
    result = self._execute_task(context, task_copy)
  File "/home/airflow/.local/lib/python3.6/site-packages/airflow/models/taskinstance.py", line 1361, in _execute_task
    result = task_copy.execute(context=context)
  File "/home/airflow/.local/lib/python3.6/site-packages/airflow/operators/python.py", line 150, in execute
    return_value = self.execute_callable()
  File "/home/airflow/.local/lib/python3.6/site-packages/airflow/operators/python.py", line 161, in execute_callable
    return self.python_callable(*self.op_args, **self.op_kwargs)
  File "/opt/airflow/dags/my_elastic_search_dag.py", line 29, in random_fail_task
    raise Exception('This task randomly failed')
Exception: This task randomly failed
[2022-12-06 09:11:47,991] {taskinstance.py:1551} INFO - Marking task as UP_FOR_RETRY. dag_id=my_elastic_search_dag, task_id=CheckElasticSearchConnexion, execution_date=20221205T000000, start_date=20221206T091147, end_date=20221206T091147
[2022-12-06 09:11:48,008] {local_task_job.py:151} INFO - Task exited with return code 1
[2022-12-06 10:00:48,846] {taskinstance.py:896} INFO - Dependencies all met for <TaskInstance: my_elastic_search_dag.CheckElasticSearchConnexion 2022-12-05T00:00:00+00:00 [queued]>
[2022-12-06 10:00:48,856] {taskinstance.py:896} INFO - Dependencies all met for <TaskInstance: my_elastic_search_dag.CheckElasticSearchConnexion 2022-12-05T00:00:00+00:00 [queued]>
[2022-12-06 10:00:48,856] {taskinstance.py:1087} INFO - 
--------------------------------------------------------------------------------
[2022-12-06 10:00:48,856] {taskinstance.py:1088} INFO - Starting attempt 4 of 51
[2022-12-06 10:00:48,856] {taskinstance.py:1089} INFO - 
--------------------------------------------------------------------------------
[2022-12-06 10:00:48,869] {taskinstance.py:1107} INFO - Executing <Task(PythonOperator): CheckElasticSearchConnexion> on 2022-12-05T00:00:00+00:00
[2022-12-06 10:00:48,872] {standard_task_runner.py:52} INFO - Started process 351 to run task
[2022-12-06 10:00:48,876] {standard_task_runner.py:76} INFO - Running: ['***', 'tasks', 'run', 'my_elastic_search_dag', 'CheckElasticSearchConnexion', '2022-12-05T00:00:00+00:00', '--job-id', '9', '--pool', 'default_pool', '--raw', '--subdir', 'DAGS_FOLDER/my_elastic_search_dag.py', '--cfg-path', '/tmp/tmppr999pjv', '--error-file', '/tmp/tmpr8uh0lwa']
[2022-12-06 10:00:48,876] {standard_task_runner.py:77} INFO - Job 9: Subtask CheckElasticSearchConnexion
[2022-12-06 10:00:48,916] {logging_mixin.py:104} INFO - Running <TaskInstance: my_elastic_search_dag.CheckElasticSearchConnexion 2022-12-05T00:00:00+00:00 [running]> on host 3d95da7470fe
[2022-12-06 10:00:48,957] {taskinstance.py:1302} INFO - Exporting the following env vars:
AIRFLOW_CTX_DAG_OWNER=***
AIRFLOW_CTX_DAG_ID=my_elastic_search_dag
AIRFLOW_CTX_TASK_ID=CheckElasticSearchConnexion
AIRFLOW_CTX_EXECUTION_DATE=2022-12-05T00:00:00+00:00
AIRFLOW_CTX_DAG_RUN_ID=scheduled__2022-12-05T00:00:00+00:00
[2022-12-06 10:00:48,957] {logging_mixin.py:104} INFO - 46
[2022-12-06 10:00:48,957] {taskinstance.py:1501} ERROR - Task failed with exception
Traceback (most recent call last):
  File "/home/airflow/.local/lib/python3.6/site-packages/airflow/models/taskinstance.py", line 1157, in _run_raw_task
    self._prepare_and_execute_task_with_callbacks(context, task)
  File "/home/airflow/.local/lib/python3.6/site-packages/airflow/models/taskinstance.py", line 1331, in _prepare_and_execute_task_with_callbacks
    result = self._execute_task(context, task_copy)
  File "/home/airflow/.local/lib/python3.6/site-packages/airflow/models/taskinstance.py", line 1361, in _execute_task
    result = task_copy.execute(context=context)
  File "/home/airflow/.local/lib/python3.6/site-packages/airflow/operators/python.py", line 150, in execute
    return_value = self.execute_callable()
  File "/home/airflow/.local/lib/python3.6/site-packages/airflow/operators/python.py", line 161, in execute_callable
    return self.python_callable(*self.op_args, **self.op_kwargs)
  File "/opt/airflow/dags/my_elastic_search_dag.py", line 29, in random_fail_task
    raise Exception('This task randomly failed')
Exception: This task randomly failed
[2022-12-06 10:00:48,959] {taskinstance.py:1551} INFO - Marking task as UP_FOR_RETRY. dag_id=my_elastic_search_dag, task_id=CheckElasticSearchConnexion, execution_date=20221205T000000, start_date=20221206T100048, end_date=20221206T100048
[2022-12-06 10:00:49,009] {local_task_job.py:151} INFO - Task exited with return code 1
[2022-12-06 10:20:25,627] {taskinstance.py:896} INFO - Dependencies all met for <TaskInstance: my_elastic_search_dag.CheckElasticSearchConnexion 2022-12-05T00:00:00+00:00 [queued]>
[2022-12-06 10:20:25,646] {taskinstance.py:896} INFO - Dependencies all met for <TaskInstance: my_elastic_search_dag.CheckElasticSearchConnexion 2022-12-05T00:00:00+00:00 [queued]>
[2022-12-06 10:20:25,646] {taskinstance.py:1087} INFO - 
--------------------------------------------------------------------------------
[2022-12-06 10:20:25,647] {taskinstance.py:1088} INFO - Starting attempt 4 of 51
[2022-12-06 10:20:25,647] {taskinstance.py:1089} INFO - 
--------------------------------------------------------------------------------
[2022-12-06 10:20:25,656] {taskinstance.py:1107} INFO - Executing <Task(PythonOperator): CheckElasticSearchConnexion> on 2022-12-05T00:00:00+00:00
[2022-12-06 10:20:25,661] {standard_task_runner.py:52} INFO - Started process 252 to run task
[2022-12-06 10:20:25,666] {standard_task_runner.py:76} INFO - Running: ['***', 'tasks', 'run', 'my_elastic_search_dag', 'CheckElasticSearchConnexion', '2022-12-05T00:00:00+00:00', '--job-id', '5', '--pool', 'default_pool', '--raw', '--subdir', 'DAGS_FOLDER/my_elastic_search_dag.py', '--cfg-path', '/tmp/tmp9wjkm3po', '--error-file', '/tmp/tmp1lvrpkdd']
[2022-12-06 10:20:25,667] {standard_task_runner.py:77} INFO - Job 5: Subtask CheckElasticSearchConnexion
[2022-12-06 10:20:25,729] {logging_mixin.py:104} INFO - Running <TaskInstance: my_elastic_search_dag.CheckElasticSearchConnexion 2022-12-05T00:00:00+00:00 [running]> on host 33da1fe70ee2
[2022-12-06 10:20:25,786] {taskinstance.py:1302} INFO - Exporting the following env vars:
AIRFLOW_CTX_DAG_OWNER=***
AIRFLOW_CTX_DAG_ID=my_elastic_search_dag
AIRFLOW_CTX_TASK_ID=CheckElasticSearchConnexion
AIRFLOW_CTX_EXECUTION_DATE=2022-12-05T00:00:00+00:00
AIRFLOW_CTX_DAG_RUN_ID=scheduled__2022-12-05T00:00:00+00:00
[2022-12-06 10:20:25,787] {logging_mixin.py:104} INFO - 89
[2022-12-06 10:20:25,787] {taskinstance.py:1501} ERROR - Task failed with exception
Traceback (most recent call last):
  File "/home/airflow/.local/lib/python3.6/site-packages/airflow/models/taskinstance.py", line 1157, in _run_raw_task
    self._prepare_and_execute_task_with_callbacks(context, task)
  File "/home/airflow/.local/lib/python3.6/site-packages/airflow/models/taskinstance.py", line 1331, in _prepare_and_execute_task_with_callbacks
    result = self._execute_task(context, task_copy)
  File "/home/airflow/.local/lib/python3.6/site-packages/airflow/models/taskinstance.py", line 1361, in _execute_task
    result = task_copy.execute(context=context)
  File "/home/airflow/.local/lib/python3.6/site-packages/airflow/operators/python.py", line 150, in execute
    return_value = self.execute_callable()
  File "/home/airflow/.local/lib/python3.6/site-packages/airflow/operators/python.py", line 161, in execute_callable
    return self.python_callable(*self.op_args, **self.op_kwargs)
  File "/opt/airflow/dags/my_elastic_search_dag.py", line 29, in random_fail_task
    raise Exception('This task randomly failed')
Exception: This task randomly failed
[2022-12-06 10:20:25,789] {taskinstance.py:1551} INFO - Marking task as UP_FOR_RETRY. dag_id=my_elastic_search_dag, task_id=CheckElasticSearchConnexion, execution_date=20221205T000000, start_date=20221206T102025, end_date=20221206T102025
[2022-12-06 10:20:25,840] {local_task_job.py:151} INFO - Task exited with return code 1
