[2022-12-06 13:28:47,591] {taskinstance.py:896} INFO - Dependencies all met for <TaskInstance: my_mongo_db_dag.CheckMongoDBConnexion 2022-12-06T13:27:55.483181+00:00 [queued]>
[2022-12-06 13:28:47,599] {taskinstance.py:896} INFO - Dependencies all met for <TaskInstance: my_mongo_db_dag.CheckMongoDBConnexion 2022-12-06T13:27:55.483181+00:00 [queued]>
[2022-12-06 13:28:47,600] {taskinstance.py:1087} INFO - 
--------------------------------------------------------------------------------
[2022-12-06 13:28:47,600] {taskinstance.py:1088} INFO - Starting attempt 2 of 51
[2022-12-06 13:28:47,600] {taskinstance.py:1089} INFO - 
--------------------------------------------------------------------------------
[2022-12-06 13:28:47,611] {taskinstance.py:1107} INFO - Executing <Task(PythonOperator): CheckMongoDBConnexion> on 2022-12-06T13:27:55.483181+00:00
[2022-12-06 13:28:47,615] {standard_task_runner.py:52} INFO - Started process 959 to run task
[2022-12-06 13:28:47,618] {standard_task_runner.py:76} INFO - Running: ['***', 'tasks', 'run', 'my_mongo_db_dag', 'CheckMongoDBConnexion', '2022-12-06T13:27:55.483181+00:00', '--job-id', '52', '--pool', 'default_pool', '--raw', '--subdir', 'DAGS_FOLDER/my_mongo_db_dag.py', '--cfg-path', '/tmp/tmp4b6t844j', '--error-file', '/tmp/tmp8vb57etv']
[2022-12-06 13:28:47,618] {standard_task_runner.py:77} INFO - Job 52: Subtask CheckMongoDBConnexion
[2022-12-06 13:28:47,653] {logging_mixin.py:104} INFO - Running <TaskInstance: my_mongo_db_dag.CheckMongoDBConnexion 2022-12-06T13:27:55.483181+00:00 [running]> on host 2e62a70a5623
[2022-12-06 13:28:47,689] {taskinstance.py:1302} INFO - Exporting the following env vars:
AIRFLOW_CTX_DAG_OWNER=***
AIRFLOW_CTX_DAG_ID=my_mongo_db_dag
AIRFLOW_CTX_TASK_ID=CheckMongoDBConnexion
AIRFLOW_CTX_EXECUTION_DATE=2022-12-06T13:27:55.483181+00:00
AIRFLOW_CTX_DAG_RUN_ID=scheduled__2022-12-06T13:27:55.483181+00:00
[2022-12-06 13:28:47,690] {logging_mixin.py:104} INFO - 36
[2022-12-06 13:28:47,690] {taskinstance.py:1501} ERROR - Task failed with exception
Traceback (most recent call last):
  File "/home/airflow/.local/lib/python3.6/site-packages/airflow/models/taskinstance.py", line 1157, in _run_raw_task
    self._prepare_and_execute_task_with_callbacks(context, task)
  File "/home/airflow/.local/lib/python3.6/site-packages/airflow/models/taskinstance.py", line 1331, in _prepare_and_execute_task_with_callbacks
    result = self._execute_task(context, task_copy)
  File "/home/airflow/.local/lib/python3.6/site-packages/airflow/models/taskinstance.py", line 1361, in _execute_task
    result = task_copy.execute(context=context)
  File "/home/airflow/.local/lib/python3.6/site-packages/airflow/operators/python.py", line 150, in execute
    return_value = self.execute_callable()
  File "/home/airflow/.local/lib/python3.6/site-packages/airflow/operators/python.py", line 161, in execute_callable
    return self.python_callable(*self.op_args, **self.op_kwargs)
  File "/opt/airflow/dags/my_mongo_db_dag.py", line 29, in random_fail_task
    raise Exception('This task randomly failed')
Exception: This task randomly failed
[2022-12-06 13:28:47,692] {taskinstance.py:1551} INFO - Marking task as UP_FOR_RETRY. dag_id=my_mongo_db_dag, task_id=CheckMongoDBConnexion, execution_date=20221206T132755, start_date=20221206T132847, end_date=20221206T132847
[2022-12-06 13:28:47,709] {local_task_job.py:151} INFO - Task exited with return code 1
