[2022-12-06 10:21:59,160] {taskinstance.py:896} INFO - Dependencies all met for <TaskInstance: my_elastic_search_dag.LoadFlightsInES 2022-12-06T10:21:34.228708+00:00 [queued]>
[2022-12-06 10:21:59,172] {taskinstance.py:896} INFO - Dependencies all met for <TaskInstance: my_elastic_search_dag.LoadFlightsInES 2022-12-06T10:21:34.228708+00:00 [queued]>
[2022-12-06 10:21:59,172] {taskinstance.py:1087} INFO - 
--------------------------------------------------------------------------------
[2022-12-06 10:21:59,173] {taskinstance.py:1088} INFO - Starting attempt 1 of 1
[2022-12-06 10:21:59,173] {taskinstance.py:1089} INFO - 
--------------------------------------------------------------------------------
[2022-12-06 10:21:59,179] {taskinstance.py:1107} INFO - Executing <Task(PythonOperator): LoadFlightsInES> on 2022-12-06T10:21:34.228708+00:00
[2022-12-06 10:21:59,182] {standard_task_runner.py:52} INFO - Started process 387 to run task
[2022-12-06 10:21:59,186] {standard_task_runner.py:76} INFO - Running: ['***', 'tasks', 'run', 'my_elastic_search_dag', 'LoadFlightsInES', '2022-12-06T10:21:34.228708+00:00', '--job-id', '18', '--pool', 'default_pool', '--raw', '--subdir', 'DAGS_FOLDER/my_elastic_search_dag.py', '--cfg-path', '/tmp/tmpf24t1i2l', '--error-file', '/tmp/tmp3quha65m']
[2022-12-06 10:21:59,186] {standard_task_runner.py:77} INFO - Job 18: Subtask LoadFlightsInES
[2022-12-06 10:21:59,223] {logging_mixin.py:104} INFO - Running <TaskInstance: my_elastic_search_dag.LoadFlightsInES 2022-12-06T10:21:34.228708+00:00 [running]> on host 33da1fe70ee2
[2022-12-06 10:21:59,263] {taskinstance.py:1302} INFO - Exporting the following env vars:
AIRFLOW_CTX_DAG_OWNER=***
AIRFLOW_CTX_DAG_ID=my_elastic_search_dag
AIRFLOW_CTX_TASK_ID=LoadFlightsInES
AIRFLOW_CTX_EXECUTION_DATE=2022-12-06T10:21:34.228708+00:00
AIRFLOW_CTX_DAG_RUN_ID=manual__2022-12-06T10:21:34.228708+00:00
[2022-12-06 10:21:59,275] {base.py:150} WARNING - PUT http://elastic-search:9200/flights [status:400 request:0.004s]
[2022-12-06 10:21:59,276] {logging_mixin.py:104} INFO - L'index flights existe déjà
[2022-12-06 10:21:59,276] {logging_mixin.py:104} INFO - debut de chargement des données dans elasticsearch
[2022-12-06 10:21:59,276] {taskinstance.py:1501} ERROR - Task failed with exception
Traceback (most recent call last):
  File "/home/airflow/.local/lib/python3.6/site-packages/airflow/models/taskinstance.py", line 1157, in _run_raw_task
    self._prepare_and_execute_task_with_callbacks(context, task)
  File "/home/airflow/.local/lib/python3.6/site-packages/airflow/models/taskinstance.py", line 1331, in _prepare_and_execute_task_with_callbacks
    result = self._execute_task(context, task_copy)
  File "/home/airflow/.local/lib/python3.6/site-packages/airflow/models/taskinstance.py", line 1361, in _execute_task
    result = task_copy.execute(context=context)
  File "/home/airflow/.local/lib/python3.6/site-packages/airflow/operators/python.py", line 150, in execute
    return_value = self.execute_callable()
  File "/home/airflow/.local/lib/python3.6/site-packages/airflow/operators/python.py", line 161, in execute_callable
    return self.python_callable(*self.op_args, **self.op_kwargs)
  File "/opt/airflow/dags/my_elastic_search_dag.py", line 55, in load
    l.load(es, dict_flights)
  File "/opt/airflow/scripts/load_flight_data_in_elasticsearch.py", line 125, in load
    helpers.bulk(es, json_data, index='positions',  request_timeout=200)
  File "/home/airflow/.local/lib/python3.6/site-packages/elasticsearch/helpers/actions.py", line 304, in bulk
    for ok, item in streaming_bulk(client, actions, *args, **kwargs):
  File "/home/airflow/.local/lib/python3.6/site-packages/elasticsearch/helpers/actions.py", line 216, in streaming_bulk
    actions, chunk_size, max_chunk_bytes, client.transport.serializer
  File "/home/airflow/.local/lib/python3.6/site-packages/elasticsearch/helpers/actions.py", line 67, in _chunk_actions
    for action, data in actions:
  File "/home/airflow/.local/lib/python3.6/site-packages/elasticsearch/helpers/actions.py", line 27, in expand_action
    op_type = data.pop("_op_type", "index")
TypeError: pop() takes at most 1 argument (2 given)
[2022-12-06 10:21:59,277] {taskinstance.py:1551} INFO - Marking task as FAILED. dag_id=my_elastic_search_dag, task_id=LoadFlightsInES, execution_date=20221206T102134, start_date=20221206T102159, end_date=20221206T102159
[2022-12-06 10:21:59,343] {local_task_job.py:151} INFO - Task exited with return code 1
