[2022-12-06 08:17:59,878] {taskinstance.py:896} INFO - Dependencies all met for <TaskInstance: my_elastic_search_dag.LoadFlightsInES 2022-12-05T00:00:00+00:00 [queued]>
[2022-12-06 08:17:59,886] {taskinstance.py:896} INFO - Dependencies all met for <TaskInstance: my_elastic_search_dag.LoadFlightsInES 2022-12-05T00:00:00+00:00 [queued]>
[2022-12-06 08:17:59,887] {taskinstance.py:1087} INFO - 
--------------------------------------------------------------------------------
[2022-12-06 08:17:59,887] {taskinstance.py:1088} INFO - Starting attempt 1 of 1
[2022-12-06 08:17:59,887] {taskinstance.py:1089} INFO - 
--------------------------------------------------------------------------------
[2022-12-06 08:17:59,897] {taskinstance.py:1107} INFO - Executing <Task(PythonOperator): LoadFlightsInES> on 2022-12-05T00:00:00+00:00
[2022-12-06 08:17:59,901] {standard_task_runner.py:52} INFO - Started process 338 to run task
[2022-12-06 08:17:59,904] {standard_task_runner.py:76} INFO - Running: ['***', 'tasks', 'run', 'my_elastic_search_dag', 'LoadFlightsInES', '2022-12-05T00:00:00+00:00', '--job-id', '12', '--pool', 'default_pool', '--raw', '--subdir', 'DAGS_FOLDER/my_elastic_search_dag.py', '--cfg-path', '/tmp/tmpu53kllah', '--error-file', '/tmp/tmpo3nbrmyf']
[2022-12-06 08:17:59,905] {standard_task_runner.py:77} INFO - Job 12: Subtask LoadFlightsInES
[2022-12-06 08:17:59,941] {logging_mixin.py:104} INFO - Running <TaskInstance: my_elastic_search_dag.LoadFlightsInES 2022-12-05T00:00:00+00:00 [running]> on host dca14bec1869
[2022-12-06 08:17:59,982] {taskinstance.py:1302} INFO - Exporting the following env vars:
AIRFLOW_CTX_DAG_OWNER=***
AIRFLOW_CTX_DAG_ID=my_elastic_search_dag
AIRFLOW_CTX_TASK_ID=LoadFlightsInES
AIRFLOW_CTX_EXECUTION_DATE=2022-12-05T00:00:00+00:00
AIRFLOW_CTX_DAG_RUN_ID=scheduled__2022-12-05T00:00:00+00:00
[2022-12-06 08:17:59,991] {taskinstance.py:1501} ERROR - Task failed with exception
Traceback (most recent call last):
  File "/home/airflow/.local/lib/python3.6/site-packages/airflow/models/taskinstance.py", line 1157, in _run_raw_task
    self._prepare_and_execute_task_with_callbacks(context, task)
  File "/home/airflow/.local/lib/python3.6/site-packages/airflow/models/taskinstance.py", line 1331, in _prepare_and_execute_task_with_callbacks
    result = self._execute_task(context, task_copy)
  File "/home/airflow/.local/lib/python3.6/site-packages/airflow/models/taskinstance.py", line 1361, in _execute_task
    result = task_copy.execute(context=context)
  File "/home/airflow/.local/lib/python3.6/site-packages/airflow/operators/python.py", line 150, in execute
    return_value = self.execute_callable()
  File "/home/airflow/.local/lib/python3.6/site-packages/airflow/operators/python.py", line 161, in execute_callable
    return self.python_callable(*self.op_args, **self.op_kwargs)
  File "/opt/airflow/dags/my_elastic_search_dag.py", line 55, in load
    l.load(es, dict_flights)
  File "/opt/airflow/scripts/load_flight_data_in_elasticsearch.py", line 118, in load
    es.indices.create(index='flights', mappings=mappings)
  File "/home/airflow/.local/lib/python3.6/site-packages/elasticsearch/client/utils.py", line 84, in _wrapped
    return func(*args, params=params, **kwargs)
TypeError: create() got an unexpected keyword argument 'mappings'
[2022-12-06 08:17:59,993] {taskinstance.py:1551} INFO - Marking task as FAILED. dag_id=my_elastic_search_dag, task_id=LoadFlightsInES, execution_date=20221205T000000, start_date=20221206T081759, end_date=20221206T081759
[2022-12-06 08:18:00,038] {local_task_job.py:151} INFO - Task exited with return code 1
[2022-12-06 09:11:59,003] {taskinstance.py:896} INFO - Dependencies all met for <TaskInstance: my_elastic_search_dag.LoadFlightsInES 2022-12-05T00:00:00+00:00 [queued]>
[2022-12-06 09:11:59,016] {taskinstance.py:896} INFO - Dependencies all met for <TaskInstance: my_elastic_search_dag.LoadFlightsInES 2022-12-05T00:00:00+00:00 [queued]>
[2022-12-06 09:11:59,016] {taskinstance.py:1087} INFO - 
--------------------------------------------------------------------------------
[2022-12-06 09:11:59,016] {taskinstance.py:1088} INFO - Starting attempt 1 of 1
[2022-12-06 09:11:59,016] {taskinstance.py:1089} INFO - 
--------------------------------------------------------------------------------
[2022-12-06 09:11:59,024] {taskinstance.py:1107} INFO - Executing <Task(PythonOperator): LoadFlightsInES> on 2022-12-05T00:00:00+00:00
[2022-12-06 09:11:59,027] {standard_task_runner.py:52} INFO - Started process 631 to run task
[2022-12-06 09:11:59,030] {standard_task_runner.py:76} INFO - Running: ['***', 'tasks', 'run', 'my_elastic_search_dag', 'LoadFlightsInES', '2022-12-05T00:00:00+00:00', '--job-id', '14', '--pool', 'default_pool', '--raw', '--subdir', 'DAGS_FOLDER/my_elastic_search_dag.py', '--cfg-path', '/tmp/tmp6wczvf7_', '--error-file', '/tmp/tmpq2fnnn6p']
[2022-12-06 09:11:59,031] {standard_task_runner.py:77} INFO - Job 14: Subtask LoadFlightsInES
[2022-12-06 09:11:59,373] {logging_mixin.py:104} INFO - Running <TaskInstance: my_elastic_search_dag.LoadFlightsInES 2022-12-05T00:00:00+00:00 [running]> on host 27e998575b9f
[2022-12-06 09:11:59,467] {taskinstance.py:1302} INFO - Exporting the following env vars:
AIRFLOW_CTX_DAG_OWNER=***
AIRFLOW_CTX_DAG_ID=my_elastic_search_dag
AIRFLOW_CTX_TASK_ID=LoadFlightsInES
AIRFLOW_CTX_EXECUTION_DATE=2022-12-05T00:00:00+00:00
AIRFLOW_CTX_DAG_RUN_ID=scheduled__2022-12-05T00:00:00+00:00
[2022-12-06 09:11:59,478] {taskinstance.py:1501} ERROR - Task failed with exception
Traceback (most recent call last):
  File "/home/airflow/.local/lib/python3.6/site-packages/airflow/models/taskinstance.py", line 1157, in _run_raw_task
    self._prepare_and_execute_task_with_callbacks(context, task)
  File "/home/airflow/.local/lib/python3.6/site-packages/airflow/models/taskinstance.py", line 1331, in _prepare_and_execute_task_with_callbacks
    result = self._execute_task(context, task_copy)
  File "/home/airflow/.local/lib/python3.6/site-packages/airflow/models/taskinstance.py", line 1361, in _execute_task
    result = task_copy.execute(context=context)
  File "/home/airflow/.local/lib/python3.6/site-packages/airflow/operators/python.py", line 150, in execute
    return_value = self.execute_callable()
  File "/home/airflow/.local/lib/python3.6/site-packages/airflow/operators/python.py", line 161, in execute_callable
    return self.python_callable(*self.op_args, **self.op_kwargs)
  File "/opt/airflow/dags/my_elastic_search_dag.py", line 55, in load
    l.load(es, dict_flights)
  File "/opt/airflow/scripts/load_flight_data_in_elasticsearch.py", line 118, in load
    es.indices.create(index='flights', mappings=mappings)
  File "/home/airflow/.local/lib/python3.6/site-packages/elasticsearch/client/utils.py", line 84, in _wrapped
    return func(*args, params=params, **kwargs)
TypeError: create() got an unexpected keyword argument 'mappings'
[2022-12-06 09:11:59,480] {taskinstance.py:1551} INFO - Marking task as FAILED. dag_id=my_elastic_search_dag, task_id=LoadFlightsInES, execution_date=20221205T000000, start_date=20221206T091159, end_date=20221206T091159
[2022-12-06 09:11:59,526] {local_task_job.py:151} INFO - Task exited with return code 1
[2022-12-06 09:18:32,059] {taskinstance.py:896} INFO - Dependencies all met for <TaskInstance: my_elastic_search_dag.LoadFlightsInES 2022-12-05T00:00:00+00:00 [queued]>
[2022-12-06 09:18:32,076] {taskinstance.py:896} INFO - Dependencies all met for <TaskInstance: my_elastic_search_dag.LoadFlightsInES 2022-12-05T00:00:00+00:00 [queued]>
[2022-12-06 09:18:32,076] {taskinstance.py:1087} INFO - 
--------------------------------------------------------------------------------
[2022-12-06 09:18:32,076] {taskinstance.py:1088} INFO - Starting attempt 1 of 1
[2022-12-06 09:18:32,076] {taskinstance.py:1089} INFO - 
--------------------------------------------------------------------------------
[2022-12-06 09:18:32,085] {taskinstance.py:1107} INFO - Executing <Task(PythonOperator): LoadFlightsInES> on 2022-12-05T00:00:00+00:00
[2022-12-06 09:18:32,094] {standard_task_runner.py:76} INFO - Running: ['***', 'tasks', 'run', 'my_elastic_search_dag', 'LoadFlightsInES', '2022-12-05T00:00:00+00:00', '--job-id', '28', '--pool', 'default_pool', '--raw', '--subdir', 'DAGS_FOLDER/my_elastic_search_dag.py', '--cfg-path', '/tmp/tmp11d39tzx', '--error-file', '/tmp/tmphvwj8d_a']
[2022-12-06 09:18:32,089] {standard_task_runner.py:52} INFO - Started process 1188 to run task
[2022-12-06 09:18:32,095] {standard_task_runner.py:77} INFO - Job 28: Subtask LoadFlightsInES
[2022-12-06 09:18:32,147] {logging_mixin.py:104} INFO - Running <TaskInstance: my_elastic_search_dag.LoadFlightsInES 2022-12-05T00:00:00+00:00 [running]> on host 27e998575b9f
[2022-12-06 09:18:32,213] {taskinstance.py:1302} INFO - Exporting the following env vars:
AIRFLOW_CTX_DAG_OWNER=***
AIRFLOW_CTX_DAG_ID=my_elastic_search_dag
AIRFLOW_CTX_TASK_ID=LoadFlightsInES
AIRFLOW_CTX_EXECUTION_DATE=2022-12-05T00:00:00+00:00
AIRFLOW_CTX_DAG_RUN_ID=scheduled__2022-12-05T00:00:00+00:00
[2022-12-06 09:18:32,227] {taskinstance.py:1501} ERROR - Task failed with exception
Traceback (most recent call last):
  File "/home/airflow/.local/lib/python3.6/site-packages/airflow/models/taskinstance.py", line 1157, in _run_raw_task
    self._prepare_and_execute_task_with_callbacks(context, task)
  File "/home/airflow/.local/lib/python3.6/site-packages/airflow/models/taskinstance.py", line 1331, in _prepare_and_execute_task_with_callbacks
    result = self._execute_task(context, task_copy)
  File "/home/airflow/.local/lib/python3.6/site-packages/airflow/models/taskinstance.py", line 1361, in _execute_task
    result = task_copy.execute(context=context)
  File "/home/airflow/.local/lib/python3.6/site-packages/airflow/operators/python.py", line 150, in execute
    return_value = self.execute_callable()
  File "/home/airflow/.local/lib/python3.6/site-packages/airflow/operators/python.py", line 161, in execute_callable
    return self.python_callable(*self.op_args, **self.op_kwargs)
  File "/opt/airflow/dags/my_elastic_search_dag.py", line 55, in load
    l.load(es, dict_flights)
  File "/opt/airflow/scripts/load_flight_data_in_elasticsearch.py", line 118, in load
    es.indices.create(index='flights', mappings=mappings)
  File "/home/airflow/.local/lib/python3.6/site-packages/elasticsearch/client/utils.py", line 84, in _wrapped
    return func(*args, params=params, **kwargs)
TypeError: create() got an unexpected keyword argument 'mappings'
[2022-12-06 09:18:32,230] {taskinstance.py:1551} INFO - Marking task as FAILED. dag_id=my_elastic_search_dag, task_id=LoadFlightsInES, execution_date=20221205T000000, start_date=20221206T091832, end_date=20221206T091832
[2022-12-06 09:18:32,269] {local_task_job.py:151} INFO - Task exited with return code 1
[2022-12-06 09:53:16,972] {taskinstance.py:896} INFO - Dependencies all met for <TaskInstance: my_elastic_search_dag.LoadFlightsInES 2022-12-05T00:00:00+00:00 [queued]>
[2022-12-06 09:53:16,989] {taskinstance.py:896} INFO - Dependencies all met for <TaskInstance: my_elastic_search_dag.LoadFlightsInES 2022-12-05T00:00:00+00:00 [queued]>
[2022-12-06 09:53:16,989] {taskinstance.py:1087} INFO - 
--------------------------------------------------------------------------------
[2022-12-06 09:53:16,989] {taskinstance.py:1088} INFO - Starting attempt 1 of 1
[2022-12-06 09:53:16,989] {taskinstance.py:1089} INFO - 
--------------------------------------------------------------------------------
[2022-12-06 09:53:16,998] {taskinstance.py:1107} INFO - Executing <Task(PythonOperator): LoadFlightsInES> on 2022-12-05T00:00:00+00:00
[2022-12-06 09:53:17,006] {standard_task_runner.py:76} INFO - Running: ['***', 'tasks', 'run', 'my_elastic_search_dag', 'LoadFlightsInES', '2022-12-05T00:00:00+00:00', '--job-id', '8', '--pool', 'default_pool', '--raw', '--subdir', 'DAGS_FOLDER/my_elastic_search_dag.py', '--cfg-path', '/tmp/tmpcb_pb_e1', '--error-file', '/tmp/tmpnq2mvxk6']
[2022-12-06 09:53:17,007] {standard_task_runner.py:77} INFO - Job 8: Subtask LoadFlightsInES
[2022-12-06 09:53:17,002] {standard_task_runner.py:52} INFO - Started process 230 to run task
[2022-12-06 09:53:17,048] {logging_mixin.py:104} INFO - Running <TaskInstance: my_elastic_search_dag.LoadFlightsInES 2022-12-05T00:00:00+00:00 [running]> on host 4467c39e9c9a
[2022-12-06 09:53:17,096] {taskinstance.py:1302} INFO - Exporting the following env vars:
AIRFLOW_CTX_DAG_OWNER=***
AIRFLOW_CTX_DAG_ID=my_elastic_search_dag
AIRFLOW_CTX_TASK_ID=LoadFlightsInES
AIRFLOW_CTX_EXECUTION_DATE=2022-12-05T00:00:00+00:00
AIRFLOW_CTX_DAG_RUN_ID=scheduled__2022-12-05T00:00:00+00:00
[2022-12-06 09:53:17,106] {taskinstance.py:1501} ERROR - Task failed with exception
Traceback (most recent call last):
  File "/home/airflow/.local/lib/python3.6/site-packages/airflow/models/taskinstance.py", line 1157, in _run_raw_task
    self._prepare_and_execute_task_with_callbacks(context, task)
  File "/home/airflow/.local/lib/python3.6/site-packages/airflow/models/taskinstance.py", line 1331, in _prepare_and_execute_task_with_callbacks
    result = self._execute_task(context, task_copy)
  File "/home/airflow/.local/lib/python3.6/site-packages/airflow/models/taskinstance.py", line 1361, in _execute_task
    result = task_copy.execute(context=context)
  File "/home/airflow/.local/lib/python3.6/site-packages/airflow/operators/python.py", line 150, in execute
    return_value = self.execute_callable()
  File "/home/airflow/.local/lib/python3.6/site-packages/airflow/operators/python.py", line 161, in execute_callable
    return self.python_callable(*self.op_args, **self.op_kwargs)
  File "/opt/airflow/dags/my_elastic_search_dag.py", line 55, in load
    l.load(es, dict_flights)
  File "/opt/airflow/scripts/load_flight_data_in_elasticsearch.py", line 118, in load
    es.indices.create(index='flights', mappings=mappings)
  File "/home/airflow/.local/lib/python3.6/site-packages/elasticsearch/client/utils.py", line 84, in _wrapped
    return func(*args, params=params, **kwargs)
TypeError: create() got an unexpected keyword argument 'mappings'
[2022-12-06 09:53:17,108] {taskinstance.py:1551} INFO - Marking task as FAILED. dag_id=my_elastic_search_dag, task_id=LoadFlightsInES, execution_date=20221205T000000, start_date=20221206T095316, end_date=20221206T095317
[2022-12-06 09:53:17,141] {local_task_job.py:151} INFO - Task exited with return code 1
[2022-12-06 10:00:59,421] {taskinstance.py:896} INFO - Dependencies all met for <TaskInstance: my_elastic_search_dag.LoadFlightsInES 2022-12-05T00:00:00+00:00 [queued]>
[2022-12-06 10:00:59,429] {taskinstance.py:896} INFO - Dependencies all met for <TaskInstance: my_elastic_search_dag.LoadFlightsInES 2022-12-05T00:00:00+00:00 [queued]>
[2022-12-06 10:00:59,430] {taskinstance.py:1087} INFO - 
--------------------------------------------------------------------------------
[2022-12-06 10:00:59,430] {taskinstance.py:1088} INFO - Starting attempt 1 of 1
[2022-12-06 10:00:59,430] {taskinstance.py:1089} INFO - 
--------------------------------------------------------------------------------
[2022-12-06 10:00:59,440] {taskinstance.py:1107} INFO - Executing <Task(PythonOperator): LoadFlightsInES> on 2022-12-05T00:00:00+00:00
[2022-12-06 10:00:59,443] {standard_task_runner.py:52} INFO - Started process 377 to run task
[2022-12-06 10:00:59,447] {standard_task_runner.py:76} INFO - Running: ['***', 'tasks', 'run', 'my_elastic_search_dag', 'LoadFlightsInES', '2022-12-05T00:00:00+00:00', '--job-id', '13', '--pool', 'default_pool', '--raw', '--subdir', 'DAGS_FOLDER/my_elastic_search_dag.py', '--cfg-path', '/tmp/tmpi_4ko19y', '--error-file', '/tmp/tmpzqseex1b']
[2022-12-06 10:00:59,447] {standard_task_runner.py:77} INFO - Job 13: Subtask LoadFlightsInES
[2022-12-06 10:00:59,483] {logging_mixin.py:104} INFO - Running <TaskInstance: my_elastic_search_dag.LoadFlightsInES 2022-12-05T00:00:00+00:00 [running]> on host 3d95da7470fe
[2022-12-06 10:00:59,525] {taskinstance.py:1302} INFO - Exporting the following env vars:
AIRFLOW_CTX_DAG_OWNER=***
AIRFLOW_CTX_DAG_ID=my_elastic_search_dag
AIRFLOW_CTX_TASK_ID=LoadFlightsInES
AIRFLOW_CTX_EXECUTION_DATE=2022-12-05T00:00:00+00:00
AIRFLOW_CTX_DAG_RUN_ID=scheduled__2022-12-05T00:00:00+00:00
[2022-12-06 10:00:59,538] {base.py:150} WARNING - PUT http://elastic-search:9200/flights [status:400 request:0.004s]
[2022-12-06 10:00:59,538] {logging_mixin.py:104} INFO - L'index flights existe déjà
[2022-12-06 10:00:59,538] {logging_mixin.py:104} INFO - debut de chargement des données dans elasticsearch
[2022-12-06 10:00:59,539] {taskinstance.py:1501} ERROR - Task failed with exception
Traceback (most recent call last):
  File "/home/airflow/.local/lib/python3.6/site-packages/airflow/models/taskinstance.py", line 1157, in _run_raw_task
    self._prepare_and_execute_task_with_callbacks(context, task)
  File "/home/airflow/.local/lib/python3.6/site-packages/airflow/models/taskinstance.py", line 1331, in _prepare_and_execute_task_with_callbacks
    result = self._execute_task(context, task_copy)
  File "/home/airflow/.local/lib/python3.6/site-packages/airflow/models/taskinstance.py", line 1361, in _execute_task
    result = task_copy.execute(context=context)
  File "/home/airflow/.local/lib/python3.6/site-packages/airflow/operators/python.py", line 150, in execute
    return_value = self.execute_callable()
  File "/home/airflow/.local/lib/python3.6/site-packages/airflow/operators/python.py", line 161, in execute_callable
    return self.python_callable(*self.op_args, **self.op_kwargs)
  File "/opt/airflow/dags/my_elastic_search_dag.py", line 55, in load
    l.load(es, dict_flights)
  File "/opt/airflow/scripts/load_flight_data_in_elasticsearch.py", line 123, in load
    for doc in dict['flight']:
TypeError: list indices must be integers or slices, not str
[2022-12-06 10:00:59,540] {taskinstance.py:1551} INFO - Marking task as FAILED. dag_id=my_elastic_search_dag, task_id=LoadFlightsInES, execution_date=20221205T000000, start_date=20221206T100059, end_date=20221206T100059
[2022-12-06 10:00:59,580] {local_task_job.py:151} INFO - Task exited with return code 1
[2022-12-06 10:20:48,755] {taskinstance.py:896} INFO - Dependencies all met for <TaskInstance: my_elastic_search_dag.LoadFlightsInES 2022-12-05T00:00:00+00:00 [queued]>
[2022-12-06 10:20:48,812] {taskinstance.py:896} INFO - Dependencies all met for <TaskInstance: my_elastic_search_dag.LoadFlightsInES 2022-12-05T00:00:00+00:00 [queued]>
[2022-12-06 10:20:48,813] {taskinstance.py:1087} INFO - 
--------------------------------------------------------------------------------
[2022-12-06 10:20:48,813] {taskinstance.py:1088} INFO - Starting attempt 1 of 1
[2022-12-06 10:20:48,813] {taskinstance.py:1089} INFO - 
--------------------------------------------------------------------------------
[2022-12-06 10:20:48,822] {taskinstance.py:1107} INFO - Executing <Task(PythonOperator): LoadFlightsInES> on 2022-12-05T00:00:00+00:00
[2022-12-06 10:20:48,826] {standard_task_runner.py:52} INFO - Started process 288 to run task
[2022-12-06 10:20:48,831] {standard_task_runner.py:76} INFO - Running: ['***', 'tasks', 'run', 'my_elastic_search_dag', 'LoadFlightsInES', '2022-12-05T00:00:00+00:00', '--job-id', '11', '--pool', 'default_pool', '--raw', '--subdir', 'DAGS_FOLDER/my_elastic_search_dag.py', '--cfg-path', '/tmp/tmpoy86kqk_', '--error-file', '/tmp/tmpvq1c88km']
[2022-12-06 10:20:48,832] {standard_task_runner.py:77} INFO - Job 11: Subtask LoadFlightsInES
[2022-12-06 10:20:48,891] {logging_mixin.py:104} INFO - Running <TaskInstance: my_elastic_search_dag.LoadFlightsInES 2022-12-05T00:00:00+00:00 [running]> on host 33da1fe70ee2
[2022-12-06 10:20:48,943] {taskinstance.py:1302} INFO - Exporting the following env vars:
AIRFLOW_CTX_DAG_OWNER=***
AIRFLOW_CTX_DAG_ID=my_elastic_search_dag
AIRFLOW_CTX_TASK_ID=LoadFlightsInES
AIRFLOW_CTX_EXECUTION_DATE=2022-12-05T00:00:00+00:00
AIRFLOW_CTX_DAG_RUN_ID=scheduled__2022-12-05T00:00:00+00:00
[2022-12-06 10:20:48,960] {base.py:150} WARNING - PUT http://elastic-search:9200/flights [status:400 request:0.006s]
[2022-12-06 10:20:48,961] {logging_mixin.py:104} INFO - L'index flights existe déjà
[2022-12-06 10:20:48,961] {logging_mixin.py:104} INFO - debut de chargement des données dans elasticsearch
[2022-12-06 10:20:48,961] {taskinstance.py:1501} ERROR - Task failed with exception
Traceback (most recent call last):
  File "/home/airflow/.local/lib/python3.6/site-packages/airflow/models/taskinstance.py", line 1157, in _run_raw_task
    self._prepare_and_execute_task_with_callbacks(context, task)
  File "/home/airflow/.local/lib/python3.6/site-packages/airflow/models/taskinstance.py", line 1331, in _prepare_and_execute_task_with_callbacks
    result = self._execute_task(context, task_copy)
  File "/home/airflow/.local/lib/python3.6/site-packages/airflow/models/taskinstance.py", line 1361, in _execute_task
    result = task_copy.execute(context=context)
  File "/home/airflow/.local/lib/python3.6/site-packages/airflow/operators/python.py", line 150, in execute
    return_value = self.execute_callable()
  File "/home/airflow/.local/lib/python3.6/site-packages/airflow/operators/python.py", line 161, in execute_callable
    return self.python_callable(*self.op_args, **self.op_kwargs)
  File "/opt/airflow/dags/my_elastic_search_dag.py", line 55, in load
    l.load(es, dict_flights)
  File "/opt/airflow/scripts/load_flight_data_in_elasticsearch.py", line 125, in load
    helpers.bulk(es, json_data, index='positions',  request_timeout=200)
  File "/home/airflow/.local/lib/python3.6/site-packages/elasticsearch/helpers/actions.py", line 304, in bulk
    for ok, item in streaming_bulk(client, actions, *args, **kwargs):
  File "/home/airflow/.local/lib/python3.6/site-packages/elasticsearch/helpers/actions.py", line 216, in streaming_bulk
    actions, chunk_size, max_chunk_bytes, client.transport.serializer
  File "/home/airflow/.local/lib/python3.6/site-packages/elasticsearch/helpers/actions.py", line 67, in _chunk_actions
    for action, data in actions:
  File "/home/airflow/.local/lib/python3.6/site-packages/elasticsearch/helpers/actions.py", line 27, in expand_action
    op_type = data.pop("_op_type", "index")
TypeError: pop() takes at most 1 argument (2 given)
[2022-12-06 10:20:48,963] {taskinstance.py:1551} INFO - Marking task as FAILED. dag_id=my_elastic_search_dag, task_id=LoadFlightsInES, execution_date=20221205T000000, start_date=20221206T102048, end_date=20221206T102048
[2022-12-06 10:20:49,006] {local_task_job.py:151} INFO - Task exited with return code 1
