[2022-12-06 11:17:50,165] {taskinstance.py:896} INFO - Dependencies all met for <TaskInstance: my_mongo_db_dag.CheckMongoDBConnexion 2022-12-06T11:17:48.712978+00:00 [queued]>
[2022-12-06 11:17:50,185] {taskinstance.py:896} INFO - Dependencies all met for <TaskInstance: my_mongo_db_dag.CheckMongoDBConnexion 2022-12-06T11:17:48.712978+00:00 [queued]>
[2022-12-06 11:17:50,185] {taskinstance.py:1087} INFO - 
--------------------------------------------------------------------------------
[2022-12-06 11:17:50,185] {taskinstance.py:1088} INFO - Starting attempt 1 of 51
[2022-12-06 11:17:50,185] {taskinstance.py:1089} INFO - 
--------------------------------------------------------------------------------
[2022-12-06 11:17:50,196] {taskinstance.py:1107} INFO - Executing <Task(PythonOperator): CheckMongoDBConnexion> on 2022-12-06T11:17:48.712978+00:00
[2022-12-06 11:17:50,202] {standard_task_runner.py:52} INFO - Started process 246 to run task
[2022-12-06 11:17:50,208] {standard_task_runner.py:76} INFO - Running: ['***', 'tasks', 'run', 'my_mongo_db_dag', 'CheckMongoDBConnexion', '2022-12-06T11:17:48.712978+00:00', '--job-id', '6', '--pool', 'default_pool', '--raw', '--subdir', 'DAGS_FOLDER/my_mongo_db_dag.py', '--cfg-path', '/tmp/tmpivo3rq_x', '--error-file', '/tmp/tmpa6rr5g7g']
[2022-12-06 11:17:50,208] {standard_task_runner.py:77} INFO - Job 6: Subtask CheckMongoDBConnexion
[2022-12-06 11:17:50,257] {logging_mixin.py:104} INFO - Running <TaskInstance: my_mongo_db_dag.CheckMongoDBConnexion 2022-12-06T11:17:48.712978+00:00 [running]> on host 90b7908d868d
[2022-12-06 11:17:50,310] {taskinstance.py:1302} INFO - Exporting the following env vars:
AIRFLOW_CTX_DAG_OWNER=***
AIRFLOW_CTX_DAG_ID=my_mongo_db_dag
AIRFLOW_CTX_TASK_ID=CheckMongoDBConnexion
AIRFLOW_CTX_EXECUTION_DATE=2022-12-06T11:17:48.712978+00:00
AIRFLOW_CTX_DAG_RUN_ID=manual__2022-12-06T11:17:48.712978+00:00
[2022-12-06 11:17:50,311] {logging_mixin.py:104} INFO - 82
[2022-12-06 11:17:50,311] {taskinstance.py:1501} ERROR - Task failed with exception
Traceback (most recent call last):
  File "/home/airflow/.local/lib/python3.6/site-packages/airflow/models/taskinstance.py", line 1157, in _run_raw_task
    self._prepare_and_execute_task_with_callbacks(context, task)
  File "/home/airflow/.local/lib/python3.6/site-packages/airflow/models/taskinstance.py", line 1331, in _prepare_and_execute_task_with_callbacks
    result = self._execute_task(context, task_copy)
  File "/home/airflow/.local/lib/python3.6/site-packages/airflow/models/taskinstance.py", line 1361, in _execute_task
    result = task_copy.execute(context=context)
  File "/home/airflow/.local/lib/python3.6/site-packages/airflow/operators/python.py", line 150, in execute
    return_value = self.execute_callable()
  File "/home/airflow/.local/lib/python3.6/site-packages/airflow/operators/python.py", line 161, in execute_callable
    return self.python_callable(*self.op_args, **self.op_kwargs)
  File "/opt/airflow/dags/my_mongo_db_dag.py", line 29, in random_fail_task
    raise Exception('This task randomly failed')
Exception: This task randomly failed
[2022-12-06 11:17:50,313] {taskinstance.py:1551} INFO - Marking task as UP_FOR_RETRY. dag_id=my_mongo_db_dag, task_id=CheckMongoDBConnexion, execution_date=20221206T111748, start_date=20221206T111750, end_date=20221206T111750
[2022-12-06 11:17:50,337] {local_task_job.py:151} INFO - Task exited with return code 1
